Traceback (most recent call last):
  File "/opt/hostedtoolcache/Python/3.8.18/x64/lib/python3.8/site-packages/jupyter_cache/executors/utils.py", line 51, in single_nb_execution
    executenb(
  File "/opt/hostedtoolcache/Python/3.8.18/x64/lib/python3.8/site-packages/nbclient/client.py", line 1204, in execute
    return NotebookClient(nb=nb, resources=resources, km=km, **kwargs).execute()
  File "/opt/hostedtoolcache/Python/3.8.18/x64/lib/python3.8/site-packages/nbclient/util.py", line 84, in wrapped
    return just_run(coro(*args, **kwargs))
  File "/opt/hostedtoolcache/Python/3.8.18/x64/lib/python3.8/site-packages/nbclient/util.py", line 62, in just_run
    return loop.run_until_complete(coro)
  File "/opt/hostedtoolcache/Python/3.8.18/x64/lib/python3.8/asyncio/base_events.py", line 616, in run_until_complete
    return future.result()
  File "/opt/hostedtoolcache/Python/3.8.18/x64/lib/python3.8/site-packages/nbclient/client.py", line 663, in async_execute
    await self.async_execute_cell(
  File "/opt/hostedtoolcache/Python/3.8.18/x64/lib/python3.8/site-packages/nbclient/client.py", line 965, in async_execute_cell
    await self._check_raise_for_error(cell, cell_index, exec_reply)
  File "/opt/hostedtoolcache/Python/3.8.18/x64/lib/python3.8/site-packages/nbclient/client.py", line 862, in _check_raise_for_error
    raise CellExecutionError.from_cell_and_msg(cell, exec_reply_content)
nbclient.exceptions.CellExecutionError: An error occurred while executing the following cell:
------------------
Image(show_green_in_png(map_at(*london_location, satellite=True)))
------------------

[0;31m---------------------------------------------------------------------------[0m
[0;31mKeyError[0m                                  Traceback (most recent call last)
File [0;32m/opt/hostedtoolcache/Python/3.8.18/x64/lib/python3.8/site-packages/PIL/Image.py:3130[0m, in [0;36mfromarray[0;34m(obj, mode)[0m
[1;32m   3129[0m [38;5;28;01mtry[39;00m:
[0;32m-> 3130[0m     mode, rawmode [38;5;241m=[39m [43m_fromarray_typemap[49m[43m[[49m[43mtypekey[49m[43m][49m
[1;32m   3131[0m [38;5;28;01mexcept[39;00m [38;5;167;01mKeyError[39;00m [38;5;28;01mas[39;00m e:

[0;31mKeyError[0m: ((1, 1, 3), '<i8')

The above exception was the direct cause of the following exception:

[0;31mTypeError[0m                                 Traceback (most recent call last)
Cell [0;32mIn[23], line 1[0m
[0;32m----> 1[0m Image([43mshow_green_in_png[49m[43m([49m[43mmap_at[49m[43m([49m[38;5;241;43m*[39;49m[43mlondon_location[49m[43m,[49m[43m [49m[43msatellite[49m[38;5;241;43m=[39;49m[38;5;28;43;01mTrue[39;49;00m[43m)[49m[43m)[49m)

Cell [0;32mIn[21], line 8[0m, in [0;36mshow_green_in_png[0;34m(data)[0m
[1;32m      5[0m out [38;5;241m=[39m green[:, :, np[38;5;241m.[39mnewaxis] [38;5;241m*[39m np[38;5;241m.[39marray([[38;5;241m0[39m, [38;5;241m1[39m, [38;5;241m0[39m])[np[38;5;241m.[39mnewaxis, np[38;5;241m.[39mnewaxis, :]
[1;32m      7[0m buffer [38;5;241m=[39m BytesIO()
[0;32m----> 8[0m [43mimageio[49m[38;5;241;43m.[39;49m[43mimwrite[49m[43m([49m[43mbuffer[49m[43m,[49m[43m [49m[43mout[49m[43m,[49m[43m [49m[38;5;28;43mformat[39;49m[38;5;241;43m=[39;49m[38;5;124;43m"[39;49m[38;5;124;43mpng[39;49m[38;5;124;43m"[39;49m[43m)[49m
[1;32m      9[0m [38;5;28;01mreturn[39;00m buffer[38;5;241m.[39mgetvalue()

File [0;32m/opt/hostedtoolcache/Python/3.8.18/x64/lib/python3.8/site-packages/imageio/v2.py:397[0m, in [0;36mimwrite[0;34m(uri, im, format, **kwargs)[0m
[1;32m    395[0m imopen_args[[38;5;124m"[39m[38;5;124mlegacy_mode[39m[38;5;124m"[39m] [38;5;241m=[39m [38;5;28;01mTrue[39;00m
[1;32m    396[0m [38;5;28;01mwith[39;00m imopen(uri, [38;5;124m"[39m[38;5;124mwi[39m[38;5;124m"[39m, [38;5;241m*[39m[38;5;241m*[39mimopen_args) [38;5;28;01mas[39;00m file:
[0;32m--> 397[0m     [38;5;28;01mreturn[39;00m [43mfile[49m[38;5;241;43m.[39;49m[43mwrite[49m[43m([49m[43mim[49m[43m,[49m[43m [49m[38;5;241;43m*[39;49m[38;5;241;43m*[39;49m[43mkwargs[49m[43m)[49m

File [0;32m/opt/hostedtoolcache/Python/3.8.18/x64/lib/python3.8/site-packages/imageio/plugins/pillow.py:444[0m, in [0;36mPillowPlugin.write[0;34m(self, ndimage, mode, format, is_batch, **kwargs)[0m
[1;32m    441[0m     ndimage [38;5;241m=[39m ndimage[[38;5;28;01mNone[39;00m, [38;5;241m.[39m[38;5;241m.[39m[38;5;241m.[39m]
[1;32m    443[0m [38;5;28;01mfor[39;00m frame [38;5;129;01min[39;00m ndimage:
[0;32m--> 444[0m     pil_frame [38;5;241m=[39m [43mImage[49m[38;5;241;43m.[39;49m[43mfromarray[49m[43m([49m[43mframe[49m[43m,[49m[43m [49m[43mmode[49m[38;5;241;43m=[39;49m[43mmode[49m[43m)[49m
[1;32m    445[0m     [38;5;28;01mif[39;00m [38;5;124m"[39m[38;5;124mbits[39m[38;5;124m"[39m [38;5;129;01min[39;00m kwargs:
[1;32m    446[0m         pil_frame [38;5;241m=[39m pil_frame[38;5;241m.[39mquantize(colors[38;5;241m=[39m[38;5;241m2[39m [38;5;241m*[39m[38;5;241m*[39m kwargs[[38;5;124m"[39m[38;5;124mbits[39m[38;5;124m"[39m])

File [0;32m/opt/hostedtoolcache/Python/3.8.18/x64/lib/python3.8/site-packages/PIL/Image.py:3134[0m, in [0;36mfromarray[0;34m(obj, mode)[0m
[1;32m   3132[0m         typekey_shape, typestr [38;5;241m=[39m typekey
[1;32m   3133[0m         msg [38;5;241m=[39m [38;5;124mf[39m[38;5;124m"[39m[38;5;124mCannot handle this data type: [39m[38;5;132;01m{[39;00mtypekey_shape[38;5;132;01m}[39;00m[38;5;124m, [39m[38;5;132;01m{[39;00mtypestr[38;5;132;01m}[39;00m[38;5;124m"[39m
[0;32m-> 3134[0m         [38;5;28;01mraise[39;00m [38;5;167;01mTypeError[39;00m(msg) [38;5;28;01mfrom[39;00m [38;5;21;01me[39;00m
[1;32m   3135[0m [38;5;28;01melse[39;00m:
[1;32m   3136[0m     rawmode [38;5;241m=[39m mode

[0;31mTypeError[0m: Cannot handle this data type: (1, 1, 3), <i8
TypeError: Cannot handle this data type: (1, 1, 3), <i8

